Workbook

Sheet Read Me
A1: ResolveX - Data Workbook
A3: What is in this file
A4: Sections: the 3 sections and their student strength (CSE 50, AIDS 40, AIML 10). Blue cells are the inputs.
A5: Students: all 100 students, one login each (username cse1..cse50, aids1..aids40, aiml1..aiml10).
A6: Complaints: 100 complaints, one reported by every student. Votes, Support % and Priority Score are FORMULAS.
A7: Summary: section-wise counts (all formulas).
A8: Formula: the weights of the priority formula (blue cells). Change a weight and every score updates.
A10: How this connects to the Java project
A11: The Java program reads data/import/students.csv and data/import/complaints.csv on the first run.
A12: These two CSV files hold exactly the same data as the Students and Complaints sheets (without the formula columns).
A13: To use your own data: edit the two CSV files in Excel, delete the 4 .txt files in the data folder, run the project again.
A15: IMPORTANT - student names
... A18: Default password of every student: pass123. Admin: admin / admin123.

Sheet Summary
A1: Section | B1: Students | C1: Complaints | D1: Complaints per student | E1: Open | F1: In Progress | G1: Resolved / Closed | H1: Safety critical (open) | I1: Average support %
A2: CSE | B2: =INDEX(Sections!$B$2:$B$4,MATCH(A2,Sections!$A$2:$A$4,0)) -> 50 | C2: =COUNTIF(Complaints!$E$2:$E$101,A2) -> 50 | D2: =C2/B2 -> 1 | E2: =C2-F2-G2-COUNTIFS(Complaints!$E$2:$E$101,A2,Complaints!$K$2:$K$101,"Rejected") -> 31 | F2: =COUNTIFS(Complaints!$E$2:$E$101,A2,Complaints!$K$2:$K$101,"In Progress") -> 7 | G2: =COUNTIFS(Complaints!$E$2:$E$101,A2,Complaints!$K$2:$K$101,"Resolved")+COUNTIFS(Complaints!$E$2:$E$101,A2,Complaints!$K$2:$K$101,"Closed") -> 10 | H2: =COUNTIFS(Complaints!$E$2:$E$101,A2,Complaints!$J$2:$J$101,"YES") -> 2 | I2: =AVERAGEIF(Complaints!$E$2:$E$101,A2,Complaints!$R$2:$R$101) -> 0.2072
A3: AIDS | B3: =INDEX(Sections!$B$2:$B$4,MATCH(A3,Sections!$A$2:$A$4,0)) -> 40 | C3: =COUNTIF(Complaints!$E$2:$E$101,A3) -> 40 | D3: =C3/B3 -> 1 | E3: =C3-F3-G3-COUNTIFS(Complaints!$E$2:$E$101,A3,Complaints!$K$2:$K$101,"Rejected") -> 25 | F3: =COUNTIFS(Complaints!$E$2:$E$101,A3,Complaints!$K$2:$K$101,"In Progress") -> 7 | G3: =COUNTIFS(Complaints!$E$2:$E$101,A3,Complaints!$K$2:$K$101,"Resolved")+COUNTIFS(Complaints!$E$2:$E$101,A3,Complaints!$K$2:$K$101,"Closed") -> 7 | H3: =COUNTIFS(Complaints!$E$2:$E$101,A3,Complaints!$J$2:$J$101,"YES") -> 1 | I3: =AVERAGEIF(Complaints!$E$2:$E$101,A3,Complaints!$R$2:$R$101) -> 0.22875
A4: AIML | B4: =INDEX(Sections!$B$2:$B$4,MATCH(A4,Sections!$A$2:$A$4,0)) -> 10 | C4: =COUNTIF(Complaints!$E$2:$E$101,A4) -> 10 | D4: =C4/B4 -> 1 | E4: =C4-F4-G4-COUNTIFS(Complaints!$E$2:$E$101,A4,Complaints!$K$2:$K$101,"Rejected") -> 7 | F4: =COUNTIFS(Complaints!$E$2:$E$101,A4,Complaints!$K$2:$K$101,"In Progress") -> 2 | G4: =COUNTIFS(Complaints!$E$2:$E$101,A4,Complaints!$K$2:$K$101,"Resolved")+COUNTIFS(Complaints!$E$2:$E$101,A4,Complaints!$K$2:$K$101,"Closed") -> 1 | H4: =COUNTIFS(Complaints!$E$2:$E$101,A4,Complaints!$J$2:$J$101,"YES") -> 0 | I4: =AVERAGEIF(Complaints!$E$2:$E$101,A4,Complaints!$R$2:$R$101) -> 0.33
A5: Total | B5: =SUM(B2:B4) -> 100 | C5: =SUM(C2:C4) -> 100 | D5: =C5/B5 -> 1 | E5: =SUM(E2:E4) -> 63 | F5: =SUM(F2:F4) -> 16 | G5: =SUM(G2:G4) -> 18 | H5: =SUM(H2:H4) -> 3
A7: Open = not Resolved, Closed or Rejected and not In Progress (same rule as the admin dashboard).

Sheet Sections
A1: Section | B1: Students (strength) | C1: Students listed in Students sheet | D1: Check
A2: CSE | B2: 50 | C2: =COUNTIF(Students!$C$2:$C$101,A2) -> 50 | D2: =IF(B2=C2,"OK","MISMATCH") -> OK
A3: AIDS | B3: 40 | C3: =COUNTIF(Students!$C$2:$C$101,A3) -> 40 | D3: =IF(B3=C3,"OK","MISMATCH") -> OK
A4: AIML | B4: 10 | C4: =COUNTIF(Students!$C$2:$C$101,A4) -> 10 | D4: =IF(B4=C4,"OK","MISMATCH") -> OK
A5: Total | B5: =SUM(B2:B4) -> 100 | C5: =SUM(C2:C4) -> 100
A7: Source: section strength given by the project owner: CSE = 50, AIDS = 40, AIML = 10 students.

Sheet Students
A1: Username | B1: Full name (replace with real name) | C1: Section | D1: Default password | E1: Complaints reported
A2: cse1 | B2: Mihir Singh | C2: CSE | D2: pass123 | E2: =COUNTIF(Complaints!$F$2:$F$101,A2) -> 1
A3: cse2 | B3: Apoorva Menon | C3: CSE | D3: pass123 | E3: =COUNTIF(Complaints!$F$2:$F$101,A3) -> 1
A4: cse3 | B4: Tejas Desai | C4: CSE | D4: pass123 | E4: =COUNTIF(Complaints!$F$2:$F$101,A4) -> 1
A5: cse4 | B5: Swati Apte | C5: CSE | D5: pass123 | E5: =COUNTIF(Complaints!$F$2:$F$101,A5) -> 1
A6: cse5 | B6: Pallavi Sawant | C6: CSE | D6: pass123 | E6: =COUNTIF(Complaints!$F$2:$F$101,A6) -> 1
A7: cse6 | B7: Sayali Raut | C7: CSE | D7: pass123 | E7: =COUNTIF(Complaints!$F$2:$F$101,A7) -> 1
A8: cse7 | B8: Vaishnavi Tambe | C8: CSE | D8: pass123 | E8: =COUNTIF(Complaints!$F$2:$F$101,A8) -> 1
A9: cse8 | B9: Kiran Thakur | C9: CSE | D9: pass123 | E9: =COUNTIF(Complaints!$F$2:$F$101,A9) -> 1
A10: cse9 | B10: Vedant Sharma | C10: CSE | D10: pass123 | E10: =COUNTIF(Complaints!$F$2:$F$101,A10) -> 1
A11: cse10 | B11: Harshada Jadhav | C11: CSE | D11: pass123 | E11: =COUNTIF(Complaints!$F$2:$F$101,A11) -> 1
A12: cse11 | B12: Yash Nair | C12: CSE | D12: pass123 | E12: =COUNTIF(Complaints!$F$2:$F$101,A12) -> 1
A13: cse12 | B13: Harsh Thakur | C13: CSE | D13: pass123 | E13: =COUNTIF(Complaints!$F$2:$F$101,A13) -> 1
... A101: aiml10 | B101: Tejas Kamat | C101: AIML | D101: pass123 | E101: =COUNTIF(Complaints!$F$2:$F$101,A101) -> 1

Sheet Complaints
A1: ID | B1: Title | C1: Description | D1: Category | E1: Section | F1: Reported by (username) | G1: Student name | H1: Urgency (1-5) | I1: Severity (1-5) | J1: Safety critical | K1: Status | L1: Assigned to | M1: Admin note | N1: Days waiting | O1: Supporters (usernames) | P1: Votes | Q1: Students in section | R1: Support % | S1: Priority score (%)
A2: 1001 | B2: Frequent power cuts in Room 204 | C2: Power goes off many times a day in Room 204 and there is no backup for the lights. | D2: Electrical | E2: CSE | F2: cse1 | G2: =INDEX(Students!$B$2:$B$101,MATCH(F2,Students!$A$2:$A$101,0)) -> Mihir Singh | H2: 4 | I2: 3 | J2: NO | K2: In Progress | L2: Maintenance Team | M2: Work has started on this issue. | N2: 22 | O2: cse1;cse18;cse47;cse36;cse35;cse17;cse29;cse8;cse24 | P2: =IF(O2="",0,LEN(O2)-LEN(SUBSTITUTE(O2,";",""))+1) -> 9 | Q2: =INDEX(Sections!$B$2:$B$4,MATCH(E2,Sections!$A$2:$A$4,0)) -> 50 | R2: =P2/Q2 -> 0.18 | S2: =ROUND(Formula!$B$2*I2*20+Formula!$B$3*R2*100+Formula!$B$4*H2*20+Formula!$B$5*MIN(N2*100/Formula!$B$7,100),2)/100 -> 0.5063
A3: 1002 | B3: Software not installed in CSE Lab 1 | C3: Required IDE and Python packages are missing on many systems in CSE Lab 1. | D3: IT / Network | E3: CSE | F3: cse2 | G3: =INDEX(Students!$B$2:$B$101,MATCH(F3,Students!$A$2:$A$101,0)) -> Apoorva Menon | H3: 3 | I3: 2 | J3: NO | K3: In Progress | L3: IT Department | M3: Work has started on this issue. | N3: 9 | O3: cse2;cse1;cse11;cse40;cse48;cse21;cse18;cse29;cse8;cse16;cse25;cse6;cse28 | P3: =IF(O3="",0,LEN(O3)-LEN(SUBSTITUTE(O3,";",""))+1) -> 13 | Q3: =INDEX(Sections!$B$2:$B$4,MATCH(E3,Sections!$A$2:$A$4,0)) -> 50 | R3: =P3/Q3 -> 0.26 | S3: =ROUND(Formula!$B$2*I3*20+Formula!$B$3*R3*100+Formula!$B$4*H3*20+Formula!$B$5*MIN(N3*100/Formula!$B$7,100),2)/100 -> 0.381
A4: 1003 | B4: Ceiling fan not working in Room 204 | C4: Two ceiling fans in Room 204 do not rotate, class is very hot in the afternoon. | D4: Electrical | E4: CSE | F4: cse3 | G4: =INDEX(Students!$B$2:$B$101,MATCH(F4,Students!$A$2:$A$101,0)) -> Tejas Desai | H4: 3 | I4: 2 | J4: NO | K4: Resolved | L4: Maintenance Team | M4: Issue has been fixed. Waiting for the reporter to confirm. | N4: 14 | O4: cse3;cse7;cse38;cse41;cse18;cse22;cse29;cse48;cse39;cse21;cse16;cse40 | P4: =IF(O4="",0,LEN(O4)-LEN(SUBSTITUTE(O4,";",""))+1) -> 12 | Q4: =INDEX(Sections!$B$2:$B$4,MATCH(E4,Sections!$A$2:$A$4,0)) -> 50 | R4: =P4/Q4 -> 0.24 | S4: =ROUND(Formula!$B$2*I4*20+Formula!$B$3*R4*100+Formula!$B$4*H4*20+Formula!$B$5*MIN(N4*100/Formula!$B$7,100),2)/100 -> 0.3907
A5: 1004 | B5: Wi-Fi keeps disconnecting in Room 204 | C5: Wi-Fi drops every few minutes in Room 204, online tests and downloads fail. | D5: IT / Network | E5: CSE | F5: cse4 | G5: =INDEX(Students!$B$2:$B$101,MATCH(F5,Students!$A$2:$A$101,0)) -> Swati Apte | H5: 5 | I5: 3 | J5: NO | K5: Assigned | L5: IT Department | M5: Assigned to the concerned team. | N5: 6 | O5: cse4;cse35;cse28;cse18;cse3;cse37;cse41;cse48;cse50;cse31;cse20;cse49;cse44;cse15;cse30;cse12;cse24;cse21;cse39;cse11;cse5;cse29;cse34;cse9;cse1;cse8;cse46;cse25;cse36 | P5: =IF(O5="",0,LEN(O5)-LEN(SUBSTITUTE(O5,";",""))+1) -> 29 | Q5: =INDEX(Sections!$B$2:$B$4,MATCH(E5,Sections!$A$2:$A$4,0)) -> 50 | R5: =P5/Q5 -> 0.58 | S5: =ROUND(Formula!$B$2*I5*20+Formula!$B$3*R5*100+Formula!$B$4*H5*20+Formula!$B$5*MIN(N5*100/Formula!$B$7,100),2)/100 -> 0.633
A6: 1005 | B6: Tube lights flickering in Room 302 | C6: Lights keep flickering in Room 302 and it strains the eyes while writing. | D6: Electrical | E6: CSE | F6: cse5 | G6: =INDEX(Students!$B$2:$B$101,MATCH(F6,Students!$A$2:$A$101,0)) -> Pallavi Sawant | H6: 3 | I6: 2 | J6: NO | K6: Resolved | L6: Maintenance Team | M6: Issue has been fixed. Waiting for the reporter to confirm. | N6: 4 | O6: cse5;cse48;cse42;cse9;cse44;cse23;cse27;cse43;cse29;cse41 | P6: =IF(O6="",0,LEN(O6)-LEN(SUBSTITUTE(O6,";",""))+1) -> 10 | Q6: =INDEX(Sections!$B$2:$B$4,MATCH(E6,Sections!$A$2:$A$4,0)) -> 50 | R6: =P6/Q6 -> 0.2 | S6: =ROUND(Formula!$B$2*I6*20+Formula!$B$3*R6*100+Formula!$B$4*H6*20+Formula!$B$5*MIN(N6*100/Formula!$B$7,100),2)/100 -> 0.3433
A7: 1006 | B7: Wi-Fi keeps disconnecting in Room 401 | C7: Wi-Fi drops every few minutes in Room 401, online tests and downloads fail. | D7: IT / Network | E7: CSE | F7: cse6 | G7: =INDEX(Students!$B$2:$B$101,MATCH(F7,Students!$A$2:$A$101,0)) -> Sayali Raut | H7: 5 | I7: 3 | J7: NO | K7: Assigned | L7: IT Department | M7: Assigned to the concerned team. | N7: 23 | O7: cse6;cse26;cse45;cse8;cse25;cse29;cse49 | P7: =IF(O7="",0,LEN(O7)-LEN(SUBSTITUTE(O7,";",""))+1) -> 7 | Q7: =INDEX(Sections!$B$2:$B$4,MATCH(E7,Sections!$A$2:$A$4,0)) -> 50 | R7: =P7/Q7 -> 0.14 | S7: =ROUND(Formula!$B$2*I7*20+Formula!$B$3*R7*100+Formula!$B$4*H7*20+Formula!$B$5*MIN(N7*100/Formula!$B$7,100),2)/100 -> 0.5357
A8: 1007 | B8: Water leakage in washroom near Room 302 | C8: Water leaks from the pipe all day and the floor stays wet and slippery. | D8: Facilities | E8: CSE | F8: cse7 | G8: =INDEX(Students!$B$2:$B$101,MATCH(F8,Students!$A$2:$A$101,0)) -> Vaishnavi Tambe | H8: 5 | I8: 3 | J8: NO | K8: Submitted | N8: 4 | O8: cse7;cse22;cse38;cse26;cse24;cse1;cse47;cse48;cse45;cse18;cse32;cse46;cse25;cse28;cse31;cse3;cse2;cse20;cse4;cse33;cse44;cse12;cse15;cse10;cse14;cse11;cse43;cse49 | P8: =IF(O8="",0,LEN(O8)-LEN(SUBSTITUTE(O8,";",""))+1) -> 28 | Q8: =INDEX(Sections!$B$2:$B$4,MATCH(E8,Sections!$A$2:$A$4,0)) -> 50 | R8: =P8/Q8 -> 0.56 | S8: =ROUND(Formula!$B$2*I8*20+Formula!$B$3*R8*100+Formula!$B$4*H8*20+Formula!$B$5*MIN(N8*100/Formula!$B$7,100),2)/100 -> 0.6193
A9: 1008 | B9: Bonafide certificate delayed | C9: Bonafide certificate applied two weeks ago has not been issued yet. | D9: Administrative | E9: CSE | F9: cse8 | G9: =INDEX(Students!$B$2:$B$101,MATCH(F9,Students!$A$2:$A$101,0)) -> Kiran Thakur | H9: 3 | I9: 3 | J9: NO | K9: Submitted | N9: 3 | O9: cse8 | P9: =IF(O9="",0,LEN(O9)-LEN(SUBSTITUTE(O9,";",""))+1) -> 1 | Q9: =INDEX(Sections!$B$2:$B$4,MATCH(E9,Sections!$A$2:$A$4,0)) -> 50 | R9: =P9/Q9 -> 0.02 | S9: =ROUND(Formula!$B$2*I9*20+Formula!$B$3*R9*100+Formula!$B$4*H9*20+Formula!$B$5*MIN(N9*100/Formula!$B$7,100),2)/100 -> 0.347
A10: 1009 | B10: Frequent power cuts in Room 302 | C10: Power goes off many times a day in Room 302 and there is no backup for the lights. | D10: Electrical | E10: CSE | F10: cse9 | G10: =INDEX(Students!$B$2:$B$101,MATCH(F10,Students!$A$2:$A$101,0)) -> Vedant Sharma | H10: 4 | I10: 3 | J10: NO | K10: Under Review | M10: Complaint is being reviewed by the admin. | N10: 4 | O10: cse9;cse5;cse16;cse13 | P10: =IF(O10="",0,LEN(O10)-LEN(SUBSTITUTE(O10,";",""))+1) -> 4 | Q10: =INDEX(Sections!$B$2:$B$4,MATCH(E10,Sections!$A$2:$A$4,0)) -> 50 | R10: =P10/Q10 -> 0.08 | S10: =ROUND(Formula!$B$2*I10*20+Formula!$B$3*R10*100+Formula!$B$4*H10*20+Formula!$B$5*MIN(N10*100/Formula!$B$7,100),2)/100 -> 0.4113
A11: 1010 | B11: Cannot login to college portal | C11: Student portal shows an error after entering the correct password. | D11: IT / Network | E11: CSE | F11: cse10 | G11: =INDEX(Students!$B$2:$B$101,MATCH(F11,Students!$A$2:$A$101,0)) -> Harshada Jadhav | H11: 4 | I11: 3 | J11: NO | K11: In Progress | L11: IT Department | M11: Work has started on this issue. | N11: 10 | O11: cse10;cse25 | P11: =IF(O11="",0,LEN(O11)-LEN(SUBSTITUTE(O11,";",""))+1) -> 2 | Q11: =INDEX(Sections!$B$2:$B$4,MATCH(E11,Sections!$A$2:$A$4,0)) -> 50 | R11: =P11/Q11 -> 0.04 | S11: =ROUND(Formula!$B$2*I11*20+Formula!$B$3*R11*100+Formula!$B$4*H11*20+Formula!$B$5*MIN(N11*100/Formula!$B$7,100),2)/100 -> 0.4173
A12: 1011 | B12: Broken benches in Room 105 | C12: Several benches in Room 105 are broken and students have to stand or share. | D12: Facilities | E12: CSE | F12: cse11 | G12: =INDEX(Students!$B$2:$B$101,MATCH(F12,Students!$A$2:$A$101,0)) -> Yash Nair | H12: 3 | I12: 2 | J12: NO | K12: Reopened | L12: Civil Department | M12: Reporter says the problem is not fixed. | N12: 8 | O12: cse11;cse41;cse36;cse31;cse7;cse45;cse50;cse49;cse35;cse42;cse46;cse4;cse20 | P12: =IF(O12="",0,LEN(O12)-LEN(SUBSTITUTE(O12,";",""))+1) -> 13 | Q12: =INDEX(Sections!$B$2:$B$4,MATCH(E12,Sections!$A$2:$A$4,0)) -> 50 | R12: =P12/Q12 -> 0.26 | S12: =ROUND(Formula!$B$2*I12*20+Formula!$B$3*R12*100+Formula!$B$4*H12*20+Formula!$B$5*MIN(N12*100/Formula!$B$7,100),2)/100 -> 0.3777
A13: 1012 | B13: Library printer out of ink | C13: Printer in the library has no ink, notes and assignments cannot be printed. | D13: Facilities | E13: CSE | F13: cse12 | G13: =INDEX(Students!$B$2:$B$101,MATCH(F13,Students!$A$2:$A$101,0)) -> Harsh Thakur | H13: 2 | I13: 3 | J13: NO | K13: Submitted | N13: 2 | O13: cse12;cse28;cse16;cse8;cse46;cse5;cse7;cse47;cse39;cse26;cse3;cse9;cse30;cse37;cse2;cse20;cse50;cse25;cse43;cse45;cse31 | P13: =IF(O13="",0,LEN(O13)-LEN(SUBSTITUTE(O13,";",""))+1) -> 21 | Q13: =INDEX(Sections!$B$2:$B$4,MATCH(E13,Sections!$A$2:$A$4,0)) -> 50 | R13: =P13/Q13 -> 0.42 | S13: =ROUND(Formula!$B$2*I13*20+Formula!$B$3*R13*100+Formula!$B$4*H13*20+Formula!$B$5*MIN(N13*100/Formula!$B$7,100),2)/100 -> 0.4437
A14: 1013 | B14: Ceiling fan not working in Room 401 | C14: Two ceiling fans in Room 401 do not rotate, class is very hot in the afternoon. | D14: Electrical | E14: CSE | F14: cse13 | G14: =INDEX(Students!$B$2:$B$101,MATCH(F14,Students!$A$2:$A$101,0)) -> Amit Rane | H14: 3 | I14: 2 | J14: NO | K14: In Progress | L14: Maintenance Team | M14: Work has started on this issue. | N14: 11 | O14: cse13;cse21 | P14: =IF(O14="",0,LEN(O14)-LEN(SUBSTITUTE(O14,";",""))+1) -> 2 | Q14: =INDEX(Sections!$B$2:$B$4,MATCH(E14,Sections!$A$2:$A$4,0)) -> 50 | R14: =P14/Q14 -> 0.04 | S14: =ROUND(Formula!$B$2*I14*20+Formula!$B$3*R14*100+Formula!$B$4*H14*20+Formula!$B$5*MIN(N14*100/Formula!$B$7,100),2)/100 -> 0.3107
A15: 1014 | B15: Tube lights flickering in Room 305 | C15: Lights keep flickering in Room 305 and it strains the eyes while writing. | D15: Electrical | E15: CSE | F15: cse14 | G15: =INDEX(Students!$B$2:$B$101,MATCH(F15,Students!$A$2:$A$101,0)) -> Vaishnavi Rane | H15: 3 | I15: 3 | J15: NO | K15: Submitted | N15: 2 | O15: cse14;cse42;cse36 | P15: =IF(O15="",0,LEN(O15)-LEN(SUBSTITUTE(O15,";",""))+1) -> 3 | Q15: =INDEX(Sections!$B$2:$B$4,MATCH(E15,Sections!$A$2:$A$4,0)) -> 50 | R15: =P15/Q15 -> 0.06 | S15: =ROUND(Formula!$B$2*I15*20+Formula!$B$3*R15*100+Formula!$B$4*H15*20+Formula!$B$5*MIN(N15*100/Formula!$B$7,100),2)/100 -> 0.3577
A16: 1015 | B16: Exam hall ticket error | C16: Name spelling on the hall ticket is wrong and needs correction before exams. | D16: Administrative | E16: CSE | F16: cse15 | G16: =INDEX(Students!$B$2:$B$101,MATCH(F16,Students!$A$2:$A$101,0)) -> Sneha Naik | H16: 5 | I16: 3 | J16: NO | K16: Submitted | N16: 4 | O16: cse15;cse27;cse47 | P16: =IF(O16="",0,LEN(O16)-LEN(SUBSTITUTE(O16,";",""))+1) -> 3 | Q16: =INDEX(Sections!$B$2:$B$4,MATCH(E16,Sections!$A$2:$A$4,0)) -> 50 | R16: =P16/Q16 -> 0.06 | S16: =ROUND(Formula!$B$2*I16*20+Formula!$B$3*R16*100+Formula!$B$4*H16*20+Formula!$B$5*MIN(N16*100/Formula!$B$7,100),2)/100 -> 0.4443
A17: 1016 | B17: Broken window glass in Room 101 | C17: Window glass in Room 101 is cracked and rain water comes inside. | D17: Facilities | E17: CSE | F17: cse16 | G17: =INDEX(Students!$B$2:$B$101,MATCH(F17,Students!$A$2:$A$101,0)) -> Tanvi Shah | H17: 3 | I17: 3 | J17: NO | K17: In Progress | L17: Civil Department | M17: Work has started on this issue. | N17: 5 | O17: cse16;cse31 | P17: =IF(O17="",0,LEN(O17)-LEN(SUBSTITUTE(O17,";",""))+1) -> 2 | Q17: =INDEX(Sections!$B$2:$B$4,MATCH(E17,Sections!$A$2:$A$4,0)) -> 50 | R17: =P17/Q17 -> 0.04 | S17: =ROUND(Formula!$B$2*I17*20+Formula!$B$3*R17*100+Formula!$B$4*H17*20+Formula!$B$5*MIN(N17*100/Formula!$B$7,100),2)/100 -> 0.3607
A18: 1017 | B18: Emergency exit blocked on third floor | C18: Old furniture is kept in front of the emergency exit on the third floor. | D18: Safety | E18: CSE | F18: cse17 | G18: =INDEX(Students!$B$2:$B$101,MATCH(F18,Students!$A$2:$A$101,0)) -> Riya Gupta | H18: 5 | I18: 5 | J18: YES | K18: Assigned | L18: Maintenance Team | M18: Assigned to the concerned team. | N18: 15 | O18: cse17;cse28;cse32;cse30;cse42;cse47;cse10;cse1;cse20;cse7;cse9;cse29;cse13 | P18: =IF(O18="",0,LEN(O18)-LEN(SUBSTITUTE(O18,";",""))+1) -> 13 | Q18: =INDEX(Sections!$B$2:$B$4,MATCH(E18,Sections!$A$2:$A$4,0)) -> 50 | R18: =P18/Q18 -> 0.26 | S18: =ROUND(Formula!$B$2*I18*20+Formula!$B$3*R18*100+Formula!$B$4*H18*20+Formula!$B$5*MIN(N18*100/Formula!$B$7,100),2)/100 -> 0.691
A19: 1018 | B19: Lab systems shut down suddenly in Computer Lab 3 | C19: Systems in Computer Lab 3 restart on their own and unsaved programs are lost. | D19: IT / Network | E19: CSE | F19: cse18 | G19: =INDEX(Students!$B$2:$B$101,MATCH(F19,Students!$A$2:$A$101,0)) -> Aarti Mane | H19: 4 | I19: 3 | J19: NO | K19: In Progress | L19: IT Department | M19: Work has started on this issue. | N19: 10 | O19: cse18;cse49;cse31;cse35 | P19: =IF(O19="",0,LEN(O19)-LEN(SUBSTITUTE(O19,";",""))+1) -> 4 | Q19: =INDEX(Sections!$B$2:$B$4,MATCH(E19,Sections!$A$2:$A$4,0)) -> 50 | R19: =P19/Q19 -> 0.08 | S19: =ROUND(Formula!$B$2*I19*20+Formula!$B$3*R19*100+Formula!$B$4*H19*20+Formula!$B$5*MIN(N19*100/Formula!$B$7,100),2)/100 -> 0.4313
A20: 1019 | B20: Power sockets not working in CSE Lab 2 | C20: Most sockets near the benches in CSE Lab 2 give no power, laptops cannot be charged. | D20: Electrical | E20: CSE | F20: cse19 | G20: =INDEX(Students!$B$2:$B$101,MATCH(F20,Students!$A$2:$A$101,0)) -> Trupti Bapat | H20: 3 | I20: 3 | J20: NO | K20: Under Review | M20: Complaint is being reviewed by the admin. | N20: 6 | O20: cse19;cse14;cse22;cse11;cse46;cse20;cse2;cse7;cse13 | P20: =IF(O20="",0,LEN(O20)-LEN(SUBSTITUTE(O20,";",""))+1) -> 9 | Q20: =INDEX(Sections!$B$2:$B$4,MATCH(E20,Sections!$A$2:$A$4,0)) -> 50 | R20: =P20/Q20 -> 0.18 | S20: =ROUND(Formula!$B$2*I20*20+Formula!$B$3*R20*100+Formula!$B$4*H20*20+Formula!$B$5*MIN(N20*100/Formula!$B$7,100),2)/100 -> 0.413
A21: 1020 | B21: Classroom too noisy because of construction | C21: Construction work next to Room 105 makes it hard to hear during lectures. | D21: Academic | E21: CSE | F21: cse20 | G21: =INDEX(Students!$B$2:$B$101,MATCH(F21,Students!$A$2:$A$101,0)) -> Vivek Lad | H21: 3 | I21: 3 | J21: NO | K21: Submitted | N21: 2 | O21: cse20;cse5;cse25;cse27;cse50;cse1;cse49 | P21: =IF(O21="",0,LEN(O21)-LEN(SUBSTITUTE(O21,";",""))+1) -> 7 | Q21: =INDEX(Sections!$B$2:$B$4,MATCH(E21,Sections!$A$2:$A$4,0)) -> 50 | R21: =P21/Q21 -> 0.14 | S21: =ROUND(Formula!$B$2*I21*20+Formula!$B$3*R21*100+Formula!$B$4*H21*20+Formula!$B$5*MIN(N21*100/Formula!$B$7,100),2)/100 -> 0.3857
A22: 1021 | B22: Frequent power cuts in Room 101 | C22: Power goes off many times a day in Room 101 and there is no backup for the lights. | D22: Electrical | E22: CSE | F22: cse21 | G22: =INDEX(Students!$B$2:$B$101,MATCH(F22,Students!$A$2:$A$101,0)) -> Ananya Jadhav | H22: 4 | I22: 3 | J22: NO | K22: Closed | L22: Maintenance Team | M22: Fix confirmed by the reporter. | N22: 22 | O22: cse21;cse6;cse18;cse37;cse15;cse13;cse23;cse17 | P22: =IF(O22="",0,LEN(O22)-LEN(SUBSTITUTE(O22,";",""))+1) -> 8 | Q22: =INDEX(Sections!$B$2:$B$4,MATCH(E22,Sections!$A$2:$A$4,0)) -> 50 | R22: =P22/Q22 -> 0.16 | S22: =ROUND(Formula!$B$2*I22*20+Formula!$B$3*R22*100+Formula!$B$4*H22*20+Formula!$B$5*MIN(N22*100/Formula!$B$7,100),2)/100 -> 0.4993
A23: 1022 | B23: Power sockets not working in Computer Lab 3 | C23: Most sockets near the benches in Computer Lab 3 give no power, laptops cannot be charged. | D23: Electrical | E23: CSE | F23: cse22 | G23: =INDEX(Students!$B$2:$B$101,MATCH(F23,Students!$A$2:$A$101,0)) -> Pallavi Kadam | H23: 3 | I23: 3 | J23: NO | K23: Submitted | N23: 4 | O23: cse22;cse36 | P23: =IF(O23="",0,LEN(O23)-LEN(SUBSTITUTE(O23,";",""))+1) -> 2 | Q23: =INDEX(Sections!$B$2:$B$4,MATCH(E23,Sections!$A$2:$A$4,0)) -> 50 | R23: =P23/Q23 -> 0.04 | S23: =ROUND(Formula!$B$2*I23*20+Formula!$B$3*R23*100+Formula!$B$4*H23*20+Formula!$B$5*MIN(N23*100/Formula!$B$7,100),2)/100 -> 0.3573
A24: 1023 | B24: Tube lights flickering in Room 204 | C24: Lights keep flickering in Room 204 and it strains the eyes while writing. | D24: Electrical | E24: CSE | F24: cse23 | G24: =INDEX(Students!$B$2:$B$101,MATCH(F24,Students!$A$2:$A$101,0)) -> Jayesh Nair | H24: 3 | I24: 2 | J24: NO | K24: Resolved | L24: Maintenance Team | M24: Issue has been fixed. Waiting for the reporter to confirm. | N24: 16 | O24: cse23;cse36;cse5;cse46;cse15;cse31;cse37;cse24;cse9;cse11;cse10;cse13;cse45;cse17;cse8;cse26;cse38;cse32;cse25;cse7;cse34;cse50;cse6;cse12;cse16;cse3;cse21;cse20;cse49;cse44 | P24: =IF(O24="",0,LEN(O24)-LEN(SUBSTITUTE(O24,";",""))+1) -> 30 | Q24: =INDEX(Sections!$B$2:$B$4,MATCH(E24,Sections!$A$2:$A$4,0)) -> 50 | R24: =P24/Q24 -> 0.6 | S24: =ROUND(Formula!$B$2*I24*20+Formula!$B$3*R24*100+Formula!$B$4*H24*20+Formula!$B$5*MIN(N24*100/Formula!$B$7,100),2)/100 -> 0.5233
A25: 1024 | B25: Frequent power cuts in Room 401 | C25: Power goes off many times a day in Room 401 and there is no backup for the lights. | D25: Electrical | E25: CSE | F25: cse24 | G25: =INDEX(Students!$B$2:$B$101,MATCH(F25,Students!$A$2:$A$101,0)) -> Prachi Gaikwad | H25: 4 | I25: 3 | J25: NO | K25: Assigned | L25: Maintenance Team | M25: Assigned to the concerned team. | N25: 21 | O25: cse24;cse36;cse4;cse37;cse23;cse15;cse18;cse32;cse42;cse3;cse20;cse10;cse45 | P25: =IF(O25="",0,LEN(O25)-LEN(SUBSTITUTE(O25,";",""))+1) -> 13 | Q25: =INDEX(Sections!$B$2:$B$4,MATCH(E25,Sections!$A$2:$A$4,0)) -> 50 | R25: =P25/Q25 -> 0.26 | S25: =ROUND(Formula!$B$2*I25*20+Formula!$B$3*R25*100+Formula!$B$4*H25*20+Formula!$B$5*MIN(N25*100/Formula!$B$7,100),2)/100 -> 0.531
A26: 1025 | B26: AC not cooling in CSE Lab 1 | C26: AC in CSE Lab 1 makes noise but gives no cooling, systems heat up. | D26: Electrical | E26: CSE | F26: cse25 | G26: =INDEX(Students!$B$2:$B$101,MATCH(F26,Students!$A$2:$A$101,0)) -> Sayali Reddy | H26: 3 | I26: 3 | J26: NO | K26: Assigned | L26: Maintenance Team | M26: Assigned to the concerned team. | N26: 9 | O26: cse25;cse47;cse7;cse14;cse20;cse8;cse17 | P26: =IF(O26="",0,LEN(O26)-LEN(SUBSTITUTE(O26,";",""))+1) -> 7 | Q26: =INDEX(Sections!$B$2:$B$4,MATCH(E26,Sections!$A$2:$A$4,0)) -> 50 | R26: =P26/Q26 -> 0.14 | S26: =ROUND(Formula!$B$2*I26*20+Formula!$B$3*R26*100+Formula!$B$4*H26*20+Formula!$B$5*MIN(N26*100/Formula!$B$7,100),2)/100 -> 0.409
A27: 1026 | B27: Ceiling fan not working in Room 305 | C27: Two ceiling fans in Room 305 do not rotate, class is very hot in the afternoon. | D27: Electrical | E27: CSE | F27: cse26 | G27: =INDEX(Students!$B$2:$B$101,MATCH(F27,Students!$A$2:$A$101,0)) -> Aditya Dalvi | H27: 3 | I27: 2 | J27: NO | K27: Under Review | M27: Complaint is being reviewed by the admin. | N27: 2 | O27: cse26;cse28;cse5;cse32;cse21;cse19;cse20;cse9;cse4;cse49;cse46;cse29;cse6 | P27: =IF(O27="",0,LEN(O27)-LEN(SUBSTITUTE(O27,";",""))+1) -> 13 | Q27: =INDEX(Sections!$B$2:$B$4,MATCH(E27,Sections!$A$2:$A$4,0)) -> 50 | R27: =P27/Q27 -> 0.26 | S27: =ROUND(Formula!$B$2*I27*20+Formula!$B$3*R27*100+Formula!$B$4*H27*20+Formula!$B$5*MIN(N27*100/Formula!$B$7,100),2)/100 -> 0.3577
A28: 1027 | B28: Software not installed in Computer Lab 3 | C28: Required IDE and Python packages are missing on many systems in Computer Lab 3. | D28: IT / Network | E28: CSE | F28: cse27 | G28: =INDEX(Students!$B$2:$B$101,MATCH(F28,Students!$A$2:$A$101,0)) -> Shruti Agarwal | H28: 3 | I28: 3 | J28: NO | K28: Submitted | N28: 1 | O28: cse27;cse43;cse13;cse36;cse1;cse2;cse21;cse49;cse46;cse42;cse45;cse7;cse17;cse33;cse35;cse28;cse22;cse15;cse3;cse12;cse48;cse37;cse19;cse23;cse16;cse30;cse26;cse31;cse14;cse50;cse11;cse32;cse40;cse9;cse29;cse44 | P28: =IF(O28="",0,LEN(O28)-LEN(SUBSTITUTE(O28,";",""))+1) -> 36 | Q28: =INDEX(Sections!$B$2:$B$4,MATCH(E28,Sections!$A$2:$A$4,0)) -> 50 | R28: =P28/Q28 -> 0.72 | S28: =ROUND(Formula!$B$2*I28*20+Formula!$B$3*R28*100+Formula!$B$4*H28*20+Formula!$B$5*MIN(N28*100/Formula!$B$7,100),2)/100 -> 0.5853
A29: 1028 | B29: Broken benches in Room 302 | C29: Several benches in Room 302 are broken and students have to stand or share. | D29: Facilities | E29: CSE | F29: cse28 | G29: =INDEX(Students!$B$2:$B$101,MATCH(F29,Students!$A$2:$A$101,0)) -> Janhavi Mhatre | H29: 3 | I29: 2 | J29: NO | K29: Rejected | M29: Not a valid complaint after checking. | N29: 19 | O29: cse28;cse6;cse42;cse43 | P29: =IF(O29="",0,LEN(O29)-LEN(SUBSTITUTE(O29,";",""))+1) -> 4 | Q29: =INDEX(Sections!$B$2:$B$4,MATCH(E29,Sections!$A$2:$A$4,0)) -> 50 | R29: =P29/Q29 -> 0.08 | S29: =ROUND(Formula!$B$2*I29*20+Formula!$B$3*R29*100+Formula!$B$4*H29*20+Formula!$B$5*MIN(N29*100/Formula!$B$7,100),2)/100 -> 0.3513
A30: 1029 | B30: Ceiling fan not working in Room 302 | C30: Two ceiling fans in Room 302 do not rotate, class is very hot in the afternoon. | D30: Electrical | E30: CSE | F30: cse29 | G30: =INDEX(Students!$B$2:$B$101,MATCH(F30,Students!$A$2:$A$101,0)) -> Akash Salvi | H30: 3 | I30: 2 | J30: NO | K30: In Progress | L30: Maintenance Team | M30: Work has started on this issue. | N30: 14 | O30: cse29;cse2;cse28;cse31;cse45;cse4;cse43;cse40;cse3;cse32;cse10;cse42;cse26;cse8;cse23;cse38;cse17;cse36;cse16;cse14;cse34;cse21;cse7;cse9;cse49;cse15;cse22;cse1;cse46;cse50;cse35;cse33;cse12;cse6;cse13;cse25 | P30: =IF(O30="",0,LEN(O30)-LEN(SUBSTITUTE(O30,";",""))+1) -> 36 | Q30: =INDEX(Sections!$B$2:$B$4,MATCH(E30,Sections!$A$2:$A$4,0)) -> 50 | R30: =P30/Q30 -> 0.72 | S30: =ROUND(Formula!$B$2*I30*20+Formula!$B$3*R30*100+Formula!$B$4*H30*20+Formula!$B$5*MIN(N30*100/Formula!$B$7,100),2)/100 -> 0.5587
A31: 1030 | B31: Software not installed in CSE Lab 2 | C31: Required IDE and Python packages are missing on many systems in CSE Lab 2. | D31: IT / Network | E31: CSE | F31: cse30 | G31: =INDEX(Students!$B$2:$B$101,MATCH(F31,Students!$A$2:$A$101,0)) -> Nikita Raut | H31: 3 | I31: 2 | J31: NO | K31: Under Review | M31: Complaint is being reviewed by the admin. | N31: 4 | O31: cse30;cse43;cse9;cse13;cse46;cse40;cse20;cse12;cse45;cse28;cse19 | P31: =IF(O31="",0,LEN(O31)-LEN(SUBSTITUTE(O31,";",""))+1) -> 11 | Q31: =INDEX(Sections!$B$2:$B$4,MATCH(E31,Sections!$A$2:$A$4,0)) -> 50 | R31: =P31/Q31 -> 0.22 | S31: =ROUND(Formula!$B$2*I31*20+Formula!$B$3*R31*100+Formula!$B$4*H31*20+Formula!$B$5*MIN(N31*100/Formula!$B$7,100),2)/100 -> 0.3503
A32: 1031 | B32: Timetable clash for practical batches | C32: Two practical batches have been given the same slot in Computer Lab 3. | D32: Academic | E32: CSE | F32: cse31 | G32: =INDEX(Students!$B$2:$B$101,MATCH(F32,Students!$A$2:$A$101,0)) -> Gauri Shinde | H32: 4 | I32: 3 | J32: NO | K32: Closed | L32: Department Office | M32: Fix confirmed by the reporter. | N32: 18 | O32: cse31;cse28;cse37;cse50;cse13;cse6;cse26;cse25;cse24;cse14;cse40;cse36;cse38;cse33;cse17;cse21;cse16;cse22;cse46;cse48;cse7;cse43;cse9;cse39;cse3;cse15;cse27 | P32: =IF(O32="",0,LEN(O32)-LEN(SUBSTITUTE(O32,";",""))+1) -> 27 | Q32: =INDEX(Sections!$B$2:$B$4,MATCH(E32,Sections!$A$2:$A$4,0)) -> 50 | R32: =P32/Q32 -> 0.54 | S32: =ROUND(Formula!$B$2*I32*20+Formula!$B$3*R32*100+Formula!$B$4*H32*20+Formula!$B$5*MIN(N32*100/Formula!$B$7,100),2)/100 -> 0.619
A33: 1032 | B33: Lab computers very slow in CSE Lab 1 | C33: Computers in CSE Lab 1 take around 10 minutes to start and hang while coding. | D33: IT / Network | E33: CSE | F33: cse32 | G33: =INDEX(Students!$B$2:$B$101,MATCH(F33,Students!$A$2:$A$101,0)) -> Payal Menon | H33: 3 | I33: 3 | J33: NO | K33: Submitted | N33: 2 | O33: cse32;cse15;cse20;cse41;cse27;cse30;cse46;cse3;cse18;cse19;cse6;cse44;cse43;cse45;cse22;cse5;cse25;cse34;cse28;cse24;cse11;cse14;cse40 | P33: =IF(O33="",0,LEN(O33)-LEN(SUBSTITUTE(O33,";",""))+1) -> 23 | Q33: =INDEX(Sections!$B$2:$B$4,MATCH(E33,Sections!$A$2:$A$4,0)) -> 50 | R33: =P33/Q33 -> 0.46 | S33: =ROUND(Formula!$B$2*I33*20+Formula!$B$3*R33*100+Formula!$B$4*H33*20+Formula!$B$5*MIN(N33*100/Formula!$B$7,100),2)/100 -> 0.4977
A34: 1033 | B34: Canteen hygiene problem | C34: Tables and utensils in the canteen are not cleaned properly during lunch. | D34: Facilities | E34: CSE | F34: cse33 | G34: =INDEX(Students!$B$2:$B$101,MATCH(F34,Students!$A$2:$A$101,0)) -> Swati Rao | H34: 3 | I34: 3 | J34: NO | K34: Waiting | L34: Civil Department | M34: Waiting for spare parts / approval. | N34: 7 | O34: cse33;cse45 | P34: =IF(O34="",0,LEN(O34)-LEN(SUBSTITUTE(O34,";",""))+1) -> 2 | Q34: =INDEX(Sections!$B$2:$B$4,MATCH(E34,Sections!$A$2:$A$4,0)) -> 50 | R34: =P34/Q34 -> 0.04 | S34: =ROUND(Formula!$B$2*I34*20+Formula!$B$3*R34*100+Formula!$B$4*H34*20+Formula!$B$5*MIN(N34*100/Formula!$B$7,100),2)/100 -> 0.3673
A35: 1034 | B35: Parking area has no lighting | C35: Two-wheeler parking is dark in the evening and feels unsafe after practical sessions. | D35: Facilities | E35: CSE | F35: cse34 | G35: =INDEX(Students!$B$2:$B$101,MATCH(F35,Students!$A$2:$A$101,0)) -> Tanvi Bhat | H35: 3 | I35: 3 | J35: NO | K35: Submitted | N35: 3 | O35: cse34;cse47;cse4;cse35;cse9 | P35: =IF(O35="",0,LEN(O35)-LEN(SUBSTITUTE(O35,";",""))+1) -> 5 | Q35: =INDEX(Sections!$B$2:$B$4,MATCH(E35,Sections!$A$2:$A$4,0)) -> 50 | R35: =P35/Q35 -> 0.1 | S35: =ROUND(Formula!$B$2*I35*20+Formula!$B$3*R35*100+Formula!$B$4*H35*20+Formula!$B$5*MIN(N35*100/Formula!$B$7,100),2)/100 -> 0.375
A36: 1035 | B36: Lab systems shut down suddenly in CSE Lab 1 | C36: Systems in CSE Lab 1 restart on their own and unsaved programs are lost. | D36: IT / Network | E36: CSE | F36: cse35 | G36: =INDEX(Students!$B$2:$B$101,MATCH(F36,Students!$A$2:$A$101,0)) -> Neel Sawant | H36: 4 | I36: 3 | J36: NO | K36: Under Review | M36: Complaint is being reviewed by the admin. | N36: 7 | O36: cse35;cse21;cse38;cse15 | P36: =IF(O36="",0,LEN(O36)-LEN(SUBSTITUTE(O36,";",""))+1) -> 4 | Q36: =INDEX(Sections!$B$2:$B$4,MATCH(E36,Sections!$A$2:$A$4,0)) -> 50 | R36: =P36/Q36 -> 0.08 | S36: =ROUND(Formula!$B$2*I36*20+Formula!$B$3*R36*100+Formula!$B$4*H36*20+Formula!$B$5*MIN(N36*100/Formula!$B$7,100),2)/100 -> 0.4213
A37: 1036 | B37: Projector not working in Room 401 | C37: Projector in Room 401 switches off after a few minutes, lectures get interrupted. | D37: Electrical | E37: CSE | F37: cse36 | G37: =INDEX(Students!$B$2:$B$101,MATCH(F37,Students!$A$2:$A$101,0)) -> Rashmi Mishra | H37: 4 | I37: 3 | J37: NO | K37: Resolved | L37: Maintenance Team | M37: Issue has been fixed. Waiting for the reporter to confirm. | N37: 10 | O37: cse36;cse45;cse18;cse1 | P37: =IF(O37="",0,LEN(O37)-LEN(SUBSTITUTE(O37,";",""))+1) -> 4 | Q37: =INDEX(Sections!$B$2:$B$4,MATCH(E37,Sections!$A$2:$A$4,0)) -> 50 | R37: =P37/Q37 -> 0.08 | S37: =ROUND(Formula!$B$2*I37*20+Formula!$B$3*R37*100+Formula!$B$4*H37*20+Formula!$B$5*MIN(N37*100/Formula!$B$7,100),2)/100 -> 0.4313
A38: 1037 | B38: Projector screen torn in Room 204 | C38: Projector screen in Room 204 is torn and the slides are not clearly visible. | D38: Academic | E38: CSE | F38: cse37 | G38: =INDEX(Students!$B$2:$B$101,MATCH(F38,Students!$A$2:$A$101,0)) -> Trupti Bhat | H38: 2 | I38: 2 | J38: NO | K38: Resolved | L38: Department Office | M38: Issue has been fixed. Waiting for the reporter to confirm. | N38: 10 | O38: cse37;cse11;cse38;cse18;cse31;cse48;cse30;cse34;cse5 | P38: =IF(O38="",0,LEN(O38)-LEN(SUBSTITUTE(O38,";",""))+1) -> 9 | Q38: =INDEX(Sections!$B$2:$B$4,MATCH(E38,Sections!$A$2:$A$4,0)) -> 50 | R38: =P38/Q38 -> 0.18 | S38: =ROUND(Formula!$B$2*I38*20+Formula!$B$3*R38*100+Formula!$B$4*H38*20+Formula!$B$5*MIN(N38*100/Formula!$B$7,100),2)/100 -> 0.3163
A39: 1038 | B39: Water leakage in washroom near Room 101 | C39: Water leaks from the pipe all day and the floor stays wet and slippery. | D39: Facilities | E39: CSE | F39: cse38 | G39: =INDEX(Students!$B$2:$B$101,MATCH(F39,Students!$A$2:$A$101,0)) -> Aditya Wagh | H39: 5 | I39: 4 | J39: NO | K39: Resolved | L39: Civil Department | M39: Issue has been fixed. Waiting for the reporter to confirm. | N39: 10 | O39: cse38;cse9;cse18;cse49;cse26;cse1;cse12;cse47;cse6;cse41;cse24 | P39: =IF(O39="",0,LEN(O39)-LEN(SUBSTITUTE(O39,";",""))+1) -> 11 | Q39: =INDEX(Sections!$B$2:$B$4,MATCH(E39,Sections!$A$2:$A$4,0)) -> 50 | R39: =P39/Q39 -> 0.22 | S39: =ROUND(Formula!$B$2*I39*20+Formula!$B$3*R39*100+Formula!$B$4*H39*20+Formula!$B$5*MIN(N39*100/Formula!$B$7,100),2)/100 -> 0.5903
A40: 1039 | B40: Drinking water cooler not working | C40: No drinking water available on the first floor, cooler is switched off. | D40: Facilities | E40: CSE | F40: cse39 | G40: =INDEX(Students!$B$2:$B$101,MATCH(F40,Students!$A$2:$A$101,0)) -> Saurabh Surve | H40: 4 | I40: 3 | J40: NO | K40: Rejected | M40: Not a valid complaint after checking. | N40: 20 | O40: cse39;cse1;cse49 | P40: =IF(O40="",0,LEN(O40)-LEN(SUBSTITUTE(O40,";",""))+1) -> 3 | Q40: =INDEX(Sections!$B$2:$B$4,MATCH(E40,Sections!$A$2:$A$4,0)) -> 50 | R40: =P40/Q40 -> 0.06 | S40: =ROUND(Formula!$B$2*I40*20+Formula!$B$3*R40*100+Formula!$B$4*H40*20+Formula!$B$5*MIN(N40*100/Formula!$B$7,100),2)/100 -> 0.4577
...

Sheet Formula
A1: Part of the score | B1: Weight | C1: How it is converted to 0-100
A2: Severity | B2: 0.35 | C2: severity (1-5) x 20
A3: Support % | B3: 0.35 | C3: votes / students of the section x 100
A4: Urgency | B4: 0.2 | C4: urgency (1-5) x 20
A5: Waiting time | B5: 0.1 | C5: days waiting x 100 / 30, maximum 100
A6: Total (must be 100%) | B6: =SUM(B2:B5) -> 1
A7: Maximum waiting days | B7: 30 | C7: After this many days the waiting part is already 100
A9: Score = 0.35 x Severity + 0.35 x Support % + 0.20 x Urgency + 0.10 x Waiting. Score is a percentage; 100% only if every part is at its maximum. Safety critical complaints keep their real score and are listed first.
A10: Support % uses the students of the SECTION, so AIML (10 students) is treated as fairly as CSE (50 students).
